<?xml version="1.0"?>
<robot xmlns:xacro="http://ros.org/wiki/xacro" name="truck">

  <!-- Define a parameter for the scale -->
  <xacro:property name="scale_factor" value="6.0" />

  <!-- Define a Base Link -->
  <link name="base_link">
    <inertial>
      <mass value="1"/>
      <inertia ixx="0.001" ixy="0.0" ixz="0.0" iyy="0.001" iyz="0.0" izz="0.001"/>
    </inertial>
  </link>
  
  <joint name="base_link_joint" type="fixed">
    <parent link="base_link"/>
    <child link="tractor"/>
    <origin xyz="1.45 0 0" rpy="0 0 1.57"/>
    <axis xyz="1 0 0"/>
  </joint>

  <!-- Joint Controller for Base Link Connection -->
  <transmission name="trans_base_link">
    <type>transmission_interface/SimpleTransmission</type>
    <joint name="base_link_joint">
      <hardwareInterface>hardware_interface/EffortJointInterface</hardwareInterface>
    </joint>
    <actuator name="motor_base_link">
      <hardwareInterface>hardware_interface/EffortJointInterface</hardwareInterface>
      <mechanicalReduction>1</mechanicalReduction>
    </actuator>
  </transmission>

  <gazebo reference="base_link_joint">
    <disableFixedJointLumping>true</disableFixedJointLumping>
  </gazebo>

  <!-- Tractor -->
  <link name="tractor">
    <visual>
      <origin xyz="0 0 ${scale_factor*0.25}" rpy="0 0 0"/>
      <geometry>
        <box size="${scale_factor*0.5} ${scale_factor*0.5} ${scale_factor*0.5}"/>
      </geometry>
      <material name="blue">
        <color rgba="0 0 1 1"/>
      </material>
    </visual>
    <collision>
      <origin xyz="0 0 ${scale_factor*0.25}" rpy="0 0 0"/>
      <geometry>
        <box size="${scale_factor*0.5} ${scale_factor*0.5} ${scale_factor*0.5}"/>
      </geometry>
      <surface>
        <friction> <!-- friction coefficients must be set to 0 allowing it to move -->
          <ode>
            <mu>0</mu>
            <mu2>0</mu2>
          </ode>
        </friction>
      </surface>
    </collision>
    <inertial>
      <mass value="1"/>
      <origin xyz="0 0 0" rpy="0 0 0"/>
      <inertia ixx="1" ixy="0" ixz="0" iyy="1" iyz="0" izz="1"/>
    </inertial>
  </link>

  <!-- Trailer -->
  <link name="trailer">
    <visual>
      <origin xyz="-${scale_factor*0.75} 0 ${scale_factor*0.25}" rpy="0 0 0"/>
      <geometry>
        <box size="${scale_factor*1} ${scale_factor*0.5} ${scale_factor*0.5}"/>
      </geometry>
      <material name="red">
        <color rgba="1 0 0 1"/>
      </material>
    </visual>
    <collision>
      <origin xyz="-${scale_factor*0.75} 0 ${scale_factor*0.25}" rpy="0 0 0"/>
      <geometry>
        <box size="${scale_factor*1} ${scale_factor*0.5} ${scale_factor*0.5}"/>
      </geometry>
      <surface>
        <friction> <!-- friction coefficients must be set to 0 allowing it to move -->
          <ode>
            <mu>0</mu>
            <mu2>0</mu2>
          </ode>
        </friction>
      </surface>
    </collision>
    <inertial>
      <mass value="1"/>
      <origin xyz="0 0 0" rpy="0 0 0"/>
      <inertia ixx="1" ixy="0" ixz="0" iyy="1" iyz="0" izz="1"/>
    </inertial>
  </link>

  <!-- Tractor-trailer Joint -->
  <joint name="hitch_joint" type="revolute">
    <parent link="tractor"/>
    <child link="trailer"/>
    <origin xyz="0 0 0" rpy="0 0 0"/>
    <axis xyz="0 0 1"/>
    <limit effort="100" velocity="1.0" lower="-1.5708" upper="1.5708"/>
  </joint>

  <!-- Joint Controller for Hitch Joint -->
  <transmission name="trans_hitch_joint">
    <type>transmission_interface/SimpleTransmission</type>
    <joint name="hitch_joint">
      <hardwareInterface>hardware_interface/EffortJointInterface</hardwareInterface>
    </joint>
    <actuator name="motor_hitch_joint">
      <hardwareInterface>hardware_interface/EffortJointInterface</hardwareInterface>
      <mechanicalReduction>1</mechanicalReduction>
    </actuator>
  </transmission>


  <!-- Gazebo plugins to control the tractor-trailer joint -->
  <!-- <gazebo>
    <plugin name="tractor_joint_controller" filename="libgazebo_ros_control.so">
      <robotNamespace>/</robotNamespace>
      <jointName>hitch_joint</jointName>
      <pid>
        <p>1.0</p>
        <i>0.1</i>
        <d>0.0</d>
        <iMax>1.0</iMax>
        <iMin>-1.0</iMin>
      </pid> 
      <alwaysOn>true</alwaysOn>
      <updateRate>100.0</updateRate>
      <publishJointState>true</publishJointState>
      <publishJointTF>true</publishJointTF>
      <legacyMode>false</legacyMode>
    </plugin>
  </gazebo> -->

  <!-- Controller Configuration -->
  <gazebo>
    <plugin name="gazebo_ros_control" filename="libgazebo_ros_control.so">
      <!-- <robotNamespace>/truck</robotNamespace>
      <robotSimType>gazebo_ros_control/DefaultRobotHWSim</robotSimType>
      <legacyModeNS>true</legacyModeNS> -->
    </plugin>
  </gazebo>

  

</robot>
